Workbook

Sheet README
A1: Supplementary Data
A2: AI-Based Research Assistants: A Task-Oriented Review of Capability, Risk and Ethical Governance in Scientific Research
A3: Second-pass scoring of the 88-cell reliability subsample (Section 3.6; Tables 2, 6a and 6b of the main text)
A5: 1. Purpose and scope
A6: What this file contains | B6: Cell-level data for the intra-rater reliability check: for each of 88 sampled tool-task cells, the first-pass Final score and the second-pass sub-factor scores (S, C, E, V) and Final score. These are the only data in the study that are not reproducible from the main-text tables.
A7: What it does not contain | B7: The full 49 x 12 score matrix is not tabulated here. Every one of its 588 cells is determined by Table 4 (task-to-category assignment), Table 5 (category-level default scores) and Table 6 (22 task-level exceptions) through the assembly rule of Section 3.5.6.
A8: Sheets | B8: README (this sheet); Data (88 rows, one per sampled cell).
A10: 2. Sampling and scoring procedure
A11: Sampling frame | B11: All 588 cells of the 49 tasks x 12 tools matrix (Section 3.5).
A12: Sample | B12: n = 88 (15% of 588). Random sample, stratified by the ten task categories, with proportional allocation by the Largest Remainder method (table below). The random seed was not recorded; the sampled cells are listed in full in sheet Data.
A13: First pass (Pass 1) | B13: Final score (1-5) recorded at the time of the original scoring and used in the matrix (category-level default or documented exception). Pass 1 sub-factor values exist only for documented exceptions (Table 6); of the 88 sampled cells, only IDs 25, 51 and 75 are exceptions, and their Pass 1 vectors (2/2/1/1, 2/2/1/1 and 2/1/2/2) are identical to the Pass 2 vectors in sheet Data.
A14: Second pass (Pass 2) | B14: Sub-factors S, C, E and V (0-2 each) were re-derived for each cell from the task name and tool name alone, without consulting the Pass 1 value; the Final score was obtained from their sum with the mapping below. Both passes were carried out by the same rater in the same session, so agreement quantifies same-session consistency, not test-retest reliability.
A15: Rater | B15: Single rater (the author). No second independent rater has scored any part of the matrix.
A17: 3. Allocation of the sample to task categories
A18: Category (order of Table 4) | C18: Tasks in category | D18: Cells in matrix (tasks x 12) | E18: Cells sampled
A19: Ideation and problem formulation | C19: 4 | D19: =C19*12 -> 48 | E19: =COUNTIF(Data!$C$2:$C$89,A19) -> 7
A20: Discovery and research-gap identification | C20: 3 | D20: =C20*12 -> 36 | E20: =COUNTIF(Data!$C$2:$C$89,A20) -> 6
A21: Literature synthesis | C21: 3 | D21: =C21*12 -> 36 | E21: =COUNTIF(Data!$C$2:$C$89,A21) -> 6
A22: Structured extraction | C22: 4 | D22: =C22*12 -> 48 | E22: =COUNTIF(Data!$C$2:$C$89,A22) -> 7
A23: Research design | C23: 6 | D23: =C23*12 -> 72 | E23: =COUNTIF(Data!$C$2:$C$89,A23) -> 11
A24: Quantitative analysis | C24: 4 | D24: =C24*12 -> 48 | E24: =COUNTIF(Data!$C$2:$C$89,A24) -> 7
A25: Coding | C25: 5 | D25: =C25*12 -> 60 | E25: =COUNTIF(Data!$C$2:$C$89,A25) -> 9
A26: Academic writing | C26: 8 | D26: =C26*12 -> 96 | E26: =COUNTIF(Data!$C$2:$C$89,A26) -> 14
A27: Adversarial review and quality control | C27: 4 | D27: =C27*12 -> 48 | E27: =COUNTIF(Data!$C$2:$C$89,A27) -> 7
A28: Verification and integrity | C28: 8 | D28: =C28*12 -> 96 | E28: =COUNTIF(Data!$C$2:$C$89,A28) -> 14
A29: Total | C29: =SUM(C19:C28) -> 49 | D29: =SUM(D19:D28) -> 588 | E29: =SUM(E19:E28) -> 88
A31: 4. Column definitions (sheet Data)
A32: ID | B32: Running number of the sampled cell (1-88).
A33: Task / Category / Tool | B33: The sampled tool-task cell. Task and category names follow Table 4; tool names follow Table 5.
A34: Pass1_Final | B34: First-pass Final score (1-5) as recorded in the matrix.
A35: Pass2_S | B35: Design suitability, second pass: 0 = task entirely outside the tool's design scope; 1 = adjacent capability applied indirectly; 2 = core, explicitly stated function.
A36: Pass2_C | B36: Native capability, second pass: 0 = output unusable without extensive rewriting; 1 = acceptable draft needing noticeable correction; 2 = near-final output needing only stylistic review.
A37: Pass2_E | B37: Evidence strength, second pass: 0 = only vendor claims or scattered anecdotes; 1 = independent non-experimental comparative evidence; 2 = independent benchmark or peer-reviewed study. Note: E = 1 in 84 of the 88 cells; E = 2 in 4 (all Semantic Scholar); E = 0 in none.
A38: Pass2_V | B38: Verification burden, second pass: 0 = every claim must be verified exhaustively; 1 = spot-check sufficient; 2 = output largely self-verifying owing to the tool's architecture. Note: V = 2 was also assigned to out-of-scope pairs with S = C = 0, where no output exists to verify (see Section 3.4.3).
A39: Pass2_Raw | B39: Sum S + C + E + V (formula; range 0-8).
A40: Pass2_Final | B40: Second-pass Final score (1-5) obtained from Pass2_Raw with the mapping below.
A42: 5. Mapping from raw score to Final score (Section 3.5.2)
A43: Raw score (S+C+E+V) | B43: Final score (1-5) and label
A44: 0-1 | B44: 1 (very poor)
A45: 2-3 | B45: 2 (poor)
...

Sheet Data
A1: ID | B1: Task | C1: Category | D1: Tool | E1: Pass1_Final | F1: Pass2_S | G1: Pass2_C | H1: Pass2_E | I1: Pass2_V | J1: Pass2_Raw | K1: Pass2_Final
A2: 1 | B2: Research-topic formulation | C2: Ideation and problem formulation | D2: Semantic Scholar | E2: 2 | F2: 1 | G2: 1 | H2: 2 | I2: 2 | J2: =SUM(F2:I2) -> 6 | K2: 4
A3: 2 | B3: Research-question formulation | C3: Ideation and problem formulation | D3: Semantic Scholar | E3: 2 | F3: 1 | G3: 1 | H3: 2 | I3: 2 | J3: =SUM(F3:I3) -> 6 | K3: 4
A4: 3 | B4: Brainstorming | C4: Ideation and problem formulation | D4: Connected Papers | E4: 3 | F4: 1 | G4: 1 | H4: 1 | I4: 2 | J4: =SUM(F4:I4) -> 5 | K4: 3
A5: 4 | B5: Novelty pre-screening | C5: Ideation and problem formulation | D5: Consensus | E5: 3 | F5: 1 | G5: 1 | H5: 1 | I5: 1 | J5: =SUM(F5:I5) -> 4 | K5: 3
A6: 5 | B6: Research-question formulation | C6: Ideation and problem formulation | D6: NotebookLM | E6: 2 | F6: 0 | G6: 1 | H6: 1 | I6: 1 | J6: =SUM(F6:I6) -> 3 | K6: 2
A7: 6 | B7: Brainstorming | C7: Ideation and problem formulation | D7: SciSpace | E7: 3 | F7: 1 | G7: 1 | H7: 1 | I7: 1 | J7: =SUM(F7:I7) -> 4 | K7: 3
A8: 7 | B8: Brainstorming | C8: Ideation and problem formulation | D8: Semantic Scholar | E8: 2 | F8: 1 | G8: 1 | H8: 2 | I8: 2 | J8: =SUM(F8:I8) -> 6 | K8: 4
A9: 8 | B9: Research-gap identification | C9: Discovery and research-gap identification | D9: NotebookLM | E9: 2 | F9: 0 | G9: 1 | H9: 1 | I9: 1 | J9: =SUM(F9:I9) -> 3 | K9: 2
A10: 9 | B10: Literature search | C10: Discovery and research-gap identification | D10: Connected Papers | E10: 4 | F10: 2 | G10: 1 | H10: 1 | I10: 2 | J10: =SUM(F10:I10) -> 6 | K10: 4
A11: 10 | B11: Literature screening | C11: Discovery and research-gap identification | D11: Perplexity | E11: 3 | F11: 1 | G11: 1 | H11: 1 | I11: 1 | J11: =SUM(F11:I11) -> 4 | K11: 3
A12: 11 | B12: Literature search | C12: Discovery and research-gap identification | D12: scite.ai | E12: 3 | F12: 1 | G12: 1 | H12: 1 | I12: 2 | J12: =SUM(F12:I12) -> 5 | K12: 3
A13: 12 | B13: Literature screening | C13: Discovery and research-gap identification | D13: NotebookLM | E13: 2 | F13: 0 | G13: 1 | H13: 1 | I13: 1 | J13: =SUM(F13:I13) -> 3 | K13: 2
... A89: 88 | B89: Experimental-leakage checking | C89: Verification and integrity | D89: scite.ai | E89: 4 | F89: 0 | G89: 0 | H89: 1 | I89: 2 | J89: =SUM(F89:I89) -> 3 | K89: 2
